<?xml version="1.0" encoding="utf-8"?>

<robot
  name="conveyor_belt_model">
  <link
    name="base_link">
    <inertial>
      <origin
        xyz="-0.00042305 -2.7756E-17 -0.017041"
        rpy="0 0 0" />
      <mass
        value="1.2" />
      <inertia
        ixx="0.00042164"
        ixy="-7.7249E-19"
        ixz="-6.2679E-08"
        iyy="0.0065622"
        iyz="1.5698E-19"
        izz="0.0065969" />
    </inertial>
    <visual>
      <origin
        xyz="0 0 0"
        rpy="0 0 0" />
      <geometry>
        <mesh
          filename="package://conveyorbelt_models/meshes/base_link.STL" />
      </geometry>
      <material
        name="">
        <color
          rgba="0.79216 0.81961 0.93333 1" />
      </material>
    </visual>
    <collision>
      <origin
        xyz="0 0 0"
        rpy="0 0 0" />
      <geometry>
        <mesh
          filename="package://conveyorbelt_models/meshes/base_link.STL" />
      </geometry>
      <surface>
        <friction>
          <ode>
            <mu>2.0</mu>
            <mu2>2.0</mu2>
	    <slip1>0.0</slip1>
	    <slip2>0.0</slip2>
          </ode>
        </friction>
      </surface>
    </collision>
  </link>
  <gazebo 
    reference="base_link">
    <material>Gazebo/WhiteGlow</material>
  </gazebo>
  <link
    name="motor_link">
    <inertial>
      <origin
        xyz="8.1799E-05 0.070043 0.00025174"
        rpy="0 0 0" />
      <mass
        value="0.3" />
      <inertia
        ixx="0.00035614"
        ixy="-9.4003E-10"
        ixz="-2.8232E-11"
        iyy="5.027E-05"
        iyz="-2.893E-09"
        izz="0.00035614" />
    </inertial>
    <visual>
      <origin
        xyz="0 0 0"
        rpy="0 0 0" />
      <geometry>
        <mesh
          filename="package://conveyorbelt_models/meshes/motor_link.STL" />
      </geometry>
      <material
        name="">
        <color
          rgba="0.79216 0.81961 0.93333 1" />
      </material>
    </visual>
    <collision>
      <origin
        xyz="0 0 0"
        rpy="0 0 0" />
      <geometry>
        <mesh
          filename="package://conveyorbelt_models/meshes/motor_link.STL" />
      </geometry>
      <surface>
        <friction>
          <ode>
            <mu>0.2</mu>
            <mu2>0.2</mu2>
	    <slip1>0.0</slip1>
	    <slip2>0.0</slip2>
          </ode>
        </friction>
      </surface>
    </collision>
  </link>
  <gazebo 
    reference="motor_link">
    <material>Gazebo/Grey</material>
  </gazebo>
  <joint
    name="motor_joint"
    type="continuous">
    <origin
      xyz="0.14492 -0.07 -0.020252"
      rpy="0 0 0" />
    <parent
      link="base_link" />
    <child
      link="motor_link" />
    <axis
      xyz="0 1 0" />
    <limit
      effort="100"
      velocity="2.2" />
    <joint_properties damping="0.0"/>
  </joint>
  <link
    name="another_link">
    <inertial>
      <origin
        xyz="-1.9429E-16 -0.07 8.3267E-17"
        rpy="0 0 0" />
      <mass
        value="0.3" />
      <inertia
        ixx="0.00035694"
        ixy="-4.7434E-20"
        ixz="5.3114E-21"
        iyy="5.0271E-05"
        iyz="4.8365E-19"
        izz="0.00035694" />
    </inertial>
    <visual>
      <origin
        xyz="0 0 0"
        rpy="0 0 0" />
      <geometry>
        <mesh
          filename="package://conveyorbelt_models/meshes/another_link.STL" />
      </geometry>
      <material
        name="">
        <color
          rgba="0.79216 0.81961 0.93333 1" />
      </material>
    </visual>
    <collision>
      <origin
        xyz="0 0 0"
        rpy="0 0 0" />
      <geometry>
        <mesh
          filename="package://conveyorbelt_models/meshes/another_link.STL" />
      </geometry>
      <surface>
        <friction>
          <ode>
            <mu>0.2</mu>
            <mu2>0.2</mu2>
	    <slip1>0.0</slip1>
	    <slip2>0.0</slip2>
          </ode>
        </friction>
      </surface>
    </collision>
  </link>
  <gazebo 
    reference="another_link">
    <material>Gazebo/Grey</material>
  </gazebo>
  <joint
    name="another_joint"
    type="continuous">
    <origin
      xyz="-0.145 0.07 -0.02"
      rpy="0 0 0" />
    <parent
      link="base_link" />
    <child
      link="another_link" />
    <axis
      xyz="0 1 0" />
    <limit
      effort="100"
      velocity="2.2" />
    <joint_properties damping="0.0"/>
  </joint>
  <link
    name="belt_link">
    <inertial>
      <origin
        xyz="0 0 0"
        rpy="0 0 0" />
      <mass
        value="0.5" />
      <inertia
        ixx="0"
        ixy="0"
        ixz="0"
        iyy="0"
        iyz="0"
        izz="0" />
    </inertial>
    <visual>
      <origin
        xyz="0 0 0"
        rpy="0 0 0" />
      <geometry>
        <mesh
          filename="package://conveyorbelt_models/meshes/belt_link.STL" />
      </geometry>
      <material
        name="">
        <color
          rgba="1 1 1 1" />
      </material>
    </visual>
    <collision>
      <origin
        xyz="0 0 0"
        rpy="0 0 0" />
      <geometry>
        <mesh
          filename="package://conveyorbelt_models/meshes/belt_link.STL" />
      </geometry>
      <surface>
        <friction>
          <ode>
            <mu>0.2</mu>
            <mu2>0.2</mu2>
	    <slip1>0.0</slip1>
	    <slip2>0.0</slip2>
          </ode>
        </friction>
      </surface>
    </collision>
  </link>
  <gazebo 
    reference="belt_link">
    <material>Gazebo/Grass</material>
  </gazebo>
  <joint
    name="belt_joint"
    type="fixed">
    <origin
      xyz="0 0 0"
      rpy="0 0 0" />
    <parent
      link="base_link" />
    <child
      link="belt_link" />
    <axis
      xyz="0 0 0" />
    <limit
      effort="100"
      velocity="2.2" />
    <joint_properties damping="0.0"/>
  </joint>

<gazebo>
  <plugin name="differential_drive_controller" filename="libgazebo_ros_diff_drive.so">

    <!-- Plugin update rate in Hz -->
    <updateRate>10</updateRate>

    <!-- Name of left joint, defaults to `left_joint` -->
    <leftJoint>another_joint</leftJoint>

    <!-- Name of right joint, defaults to `right_joint` -->
    <rightJoint>motor_joint</rightJoint>

    <!-- The distance from the center of one wheel to the other, in meters, defaults to 0.34 m -->
    <wheelSeparation>0.29</wheelSeparation>

    <!-- Diameter of the wheels, in meters, defaults to 0.15 m -->
    <wheelDiameter>0.08</wheelDiameter>

    <!-- Wheel acceleration, in rad/s^2, defaults to 0.0 rad/s^2 -->
    <wheelAcceleration>2.2</wheelAcceleration>

    <!-- Maximum torque which the wheels can produce, in Nm, defaults to 5 Nm -->
    <wheelTorque>1000</wheelTorque>

    <!-- Topic to receive geometry_msgs/Twist message commands, defaults to `cmd_vel` -->
    <commandTopic>convey1_cmd_vel</commandTopic>

    <!-- Topic to publish nav_msgs/Odometry messages, defaults to `odom` >
    <odometryTopic>odom</odometryTopic -->

    <!-- Odometry frame, defaults to `odom` >
    <odometryFrame>odom</odometryFrame -->

    <!-- Robot frame to calculate odometry from, defaults to `base_footprint` -->
    <!--robotBaseFrame>base_footprint</robotBaseFrame-->

    <!-- Odometry source, 0 for ENCODER, 1 for WORLD, defaults to WORLD -->
    <!--odometrySource>1</odometrySource-->

    <!-- Set to true to publish transforms for the wheel links, defaults to false -->
    <publishWheelTF>true</publishWheelTF>

    <!-- Set to true to publish transforms for the odometry, defaults to true >
    <publishOdom>true</publishOdom -->

    <!-- Set to true to publish sensor_msgs/JointState on /joint_states for the wheel joints, defaults to false -->
    <publishWheelJointState>true</publishWheelJointState>

    <!-- Set to true to swap right and left wheels, defaults to true -->
    <legacyMode>false</legacyMode>
  </plugin>
</gazebo>

</robot>
