<?xml version="1.0" encoding="utf-8"?>
<!-- This URDF was automatically created by SolidWorks to URDF Exporter! Originally created by Stephen Brawner (brawner@gmail.com) 
     Commit Version: 1.6.0-1-g15f4949  Build Version: 1.6.7594.29634
     For more information, please see http://wiki.ros.org/sw_urdf_exporter -->
<robot
  name="conveyor_belt_model2">
  <link
    name="base_link_convey2">
    <inertial>
      <origin
        xyz="-0.00043474 0.026209 -0.060514"
        rpy="0 0 0" />
      <mass
        value="1.3" />
      <inertia
        ixx="0.014356"
        ixy="2.186E-19"
        ixz="1.0113E-20"
        iyy="0.0026741"
        iyz="0.00050569"
        izz="0.012149" />
    </inertial>
    <visual>
      <origin
        xyz="0 0 0"
        rpy="0 0 0" />
      <geometry>
        <mesh
          filename="package://conveyor_belt_model2/meshes/base_link_convey2.STL" />
      </geometry>
      <material
        name="">
        <color
          rgba="0.79216 0.81961 0.93333 1" />
      </material>
    </visual>
    <collision>
      <origin
        xyz="0 0 0"
        rpy="0 0 0" />
      <geometry>
        <mesh
          filename="package://conveyor_belt_model2/meshes/base_link_convey2.STL" />
      </geometry>
    </collision>
  </link>
  <link
    name="convey2_motor_link">
    <inertial>
      <origin
        xyz="-0.070043 0.00025674 -6.4407E-05"
        rpy="0 0 0" />
      <mass
        value="0.3" />
      <inertia
        ixx="5.027E-05"
        ixy="2.9505E-09"
        ixz="-7.4016E-10"
        iyy="0.00035614"
        iyz="2.2671E-11"
        izz="0.00035614" />
    </inertial>
    <visual>
      <origin
        xyz="0 0 0"
        rpy="0 0 0" />
      <geometry>
        <mesh
          filename="package://conveyor_belt_model2/meshes/convey2_motor_link.STL" />
      </geometry>
      <material
        name="">
        <color
          rgba="0.79216 0.81961 0.93333 1" />
      </material>
    </visual>
    <collision>
      <origin
        xyz="0 0 0"
        rpy="0 0 0" />
      <geometry>
        <mesh
          filename="package://conveyor_belt_model2/meshes/convey2_motor_link.STL" />
      </geometry>
    </collision>
  </link>
  <joint
    name="convey2_motor_joint"
    type="continuous">
    <origin
      xyz="0.069565 -0.15776 -0.020936"
      rpy="0 0 0" />
    <parent
      link="base_link_convey2" />
    <child
      link="convey2_motor_link" />
    <axis
      xyz="-1 0 0" />
    <limit
      lower="-3.14"
      upper="3.14"
      effort="100"
      velocity="2.2" />
  </joint>
  <link
    name="convey2_another_link">
    <inertial>
      <origin
        xyz="-0.07 2.2204E-15 -6.2866E-15"
        rpy="0 0 0" />
      <mass
        value="0.3" />
      <inertia
        ixx="5.0271E-05"
        ixy="-1.0048E-20"
        ixz="-2.5529E-22"
        iyy="0.00035694"
        iyz="3.288E-21"
        izz="0.00035694" />
    </inertial>
    <visual>
      <origin
        xyz="0 0 0"
        rpy="0 0 0" />
      <geometry>
        <mesh
          filename="package://conveyor_belt_model2/meshes/convey2_another_link.STL" />
      </geometry>
      <material
        name="">
        <color
          rgba="0.79216 0.81961 0.93333 1" />
      </material>
    </visual>
    <collision>
      <origin
        xyz="0 0 0"
        rpy="0 0 0" />
      <geometry>
        <mesh
          filename="package://conveyor_belt_model2/meshes/convey2_another_link.STL" />
      </geometry>
    </collision>
  </link>
  <joint
    name="convey2_another_joint"
    type="continuous">
    <origin
      xyz="0.069565 0.1575 -0.021"
      rpy="0 0 0" />
    <parent
      link="base_link_convey2" />
    <child
      link="convey2_another_link" />
    <axis
      xyz="-1 0 0" />
    <limit
      lower="-3.14"
      upper="3.14"
      effort="100"
      velocity="2.2" />
  </joint>
  <link
    name="convey2_belt_link">
    <inertial>
      <origin
        xyz="0 0 0"
        rpy="0 0 0" />
      <mass
        value="0.5" />
      <inertia
        ixx="0"
        ixy="0"
        ixz="0"
        iyy="0"
        iyz="0"
        izz="0" />
    </inertial>
    <visual>
      <origin
        xyz="0 0 0"
        rpy="0 0 0" />
      <geometry>
        <mesh
          filename="package://conveyor_belt_model2/meshes/convey2_belt_link.STL" />
      </geometry>
      <material
        name="">
        <color
          rgba="1 1 1 1" />
      </material>
    </visual>
    <collision>
      <origin
        xyz="0 0 0"
        rpy="0 0 0" />
      <geometry>
        <mesh
          filename="package://conveyor_belt_model2/meshes/convey2_belt_link.STL" />
      </geometry>
    </collision>
  </link>
  <joint
    name="convey2_belt_joint"
    type="fixed">
    <origin
      xyz="0 0 0"
      rpy="0 0 0" />
    <parent
      link="base_link_convey2" />
    <child
      link="convey2_belt_link" />
    <axis
      xyz="0 0 0" />
    <limit
      lower="0"
      upper="0"
      effort="10"
      velocity="2.2" />
  </joint>
</robot>